<h3>Catch</h3>

<pre>( callable ) => return value or exception</pre>

<p>Calls the supplied block, function, object, or class within a try-catch. If an exception occurs, the exception is returned.</p>

<p>For example:</p>
<pre>
func = function () { return 123 + 456 }
Catch(func)
    => 579

func = function () { return j }
Catch(func)
    => "uninitialized variable: j"

Catch(){ Database("drop mytable") }
    => "nonexistent table: mytable"
</pre>

<p>The last example is written with a block immediately following the Catch call so it will be interpreted as an argument to the call.</p>